<?xml version="1.0"?>
<robot xmlns:xacro="http://www.ros.org/wiki/xacro">

  <xacro:property name="wheel_radius" value="0.0352"/>
  <xacro:property name="wheel_width" value="0.0206"/>

  <xacro:macro name="wheel" params="name x y z">
    <link name="${name}">
      <visual>
        <geometry>
          <cylinder radius="${wheel_radius}" length="${wheel_width}"/>
        </geometry>
      </visual>
    </link>

    <joint name="${name}_joint" type="continuous">
      <parent link="base_link"/>
      <child link="${name}"/>
      <origin xyz="${x} ${y} ${z}" rpy="0 1.5708 0"/>
      <axis xyz="0 0 1"/>
    </joint>
  </xacro:macro>

</robot>
